Workbook

Sheet Inputs
A1: Car Park Financial Simulator — Inputs
A2: Blue cells = inputs you can change | Black cells = calculated values
A4: Car Park Basics
A5: Total Spaces | B5: 80
A6: Operating Hours / Day | B6: 11 | C6: hrs
A7: Opening Days / Week | B7: 7
A8: Occupancy Rate | B8: 0.5 | C8: %
A9: Avg. Stay (Short-Stay) | B9: 1.9 | C9: hrs
A10: Dead Time Between Cars | B10: 10 | C10: mins
A11: Commuter % (all-day parkers) | B11: 0.35 | C11: %
A13: Vehicle Mix (must sum to 100%)
A14: % Small Car | B14: 0.85 | C14: %
A15: % Large Car / 4x4 | B15: 0.05 | C15: %
A16: % Small/Medium Van | B16: 0.05 | C16: %
A17: % Large Van | B17: 0.05 | C17: %
A18: Mix Total (should be 100%) | B18: =SUM(B14:B17) -> 1
A20: Parking Prices (VAT-inclusive, £)
A21: Vehicle Type | C21: Hourly Rate £ | D21: Daily Rate £ | E21: Daily Threshold (hrs)
A22: Small Car | C22: 5 | D22: 25 | E22: 5
A23: Large Car / 4x4 | C23: 6 | D23: 30 | E23: 5
A24: Small/Medium Van | C24: 6 | D24: 30 | E24: 5
A25: Large Van | C25: 10 | D25: 50 | E25: 5
A27: Overnight & Long-Term Parking
A28: Overnight Cars (reserved spaces) | B28: 5
A29: Overnight Flat Fee | B29: 15 | C29: £/night
A30: Long-Term Reserved Spaces | B30: 20
A31: Long-Term Weekly Fee | B31: 105 | C31: £/space/wk
A33: Indoor / Outdoor Split
A34: Number of Indoor Spaces | B34: 20
A35: Indoor Hourly Rate | B35: 6 | C35: £/hr
A36: Indoor Daily Rate | B36: 30 | C36: £/day
A38: Staff Costs
A39: Number of Staff | B39: 1
A40: Hourly Wage | B40: 12 | C40: £/hr
A41: Hours per Day | B41: 11 | C41: hrs
A42: Employer NI Rate | B42: 0.138 | C42: %
A43: Employer Pension Rate | B43: 0.03 | C43: %
A45: ANPR System (optional)
A46: ANPR Enabled? (1=Yes, 0=No) | B46: 0
A47: Installation Cost | B47: 15000 | C47: £
...

Sheet Results
A1: Car Park Financial Simulator — Results Dashboard
A2: Results update automatically when you change inputs. Green = linked from calculations.
B3: Daily | C3: Weekly | D3: Monthly | E3: Annual
A4: Space Allocation
A5: Total Spaces | B5: =Calcs!B4 -> 55
A6: of which: Outdoor | B6: =Calcs!B6 -> 35
A7: of which: Indoor | B7: =Calcs!B5 -> 20
A8: Overnight Reserved Spaces | B8: =Calcs!B2 -> 5
A9: Long-Term Reserved Spaces | B9: =Calcs!B3 -> 20
A10: Commuter Spaces | B10: =Calcs!B9 -> 19.25
A11: Short-Stay Spaces | B11: =Calcs!B10 -> 35.75
A13: Throughput
A14: Short-Stay Turnover Rate (x/day) | B14: =Calcs!B27 -> 5.3225806
A15: Commuter Vehicles / Day | B15: =Calcs!B11 -> 9.625
A16: Short-Stay Vehicles / Day | B16: =Calcs!B29 -> 95.141129
A17: Total Vehicles / Day | B17: =Calcs!B80 -> 104.76613
A18: Avg Revenue / Vehicle (gross, £) | B18: =Calcs!B81 -> 12.712407
A20: Revenue (£) — Net of VAT & Card Fees
A21: Commuter Parking | B21: =Calcs!B24 -> 268.84375 | C21: =Calcs!B24*Inputs!B7 -> 1881.9062 | D21: =Calcs!B24*Calcs!B45 -> 8148.6541 | E21: =Calcs!B24*Calcs!B46 -> 97859.125
A22: Short-Stay Parking | B22: =Calcs!B37 -> 1062.9859 | C22: =Calcs!B37*Inputs!B7 -> 7440.9012 | D22: =Calcs!B37*Calcs!B45 -> 32219.102 | E22: =Calcs!B37*Calcs!B46 -> 386926.86
A23: Overnight | B23: =Calcs!B39 -> 75 | C23: =Calcs!B39*Inputs!B7 -> 525 | D23: =Calcs!B39*Calcs!B45 -> 2273.25 | E23: =Calcs!B39*Calcs!B46 -> 27300
A24: Long-Term Permits | B24: =Calcs!B40 -> 300 | C24: =Calcs!B40*Inputs!B7 -> 2100 | D24: =Calcs!B40*Calcs!B45 -> 9093 | E24: =Calcs!B40*Calcs!B46 -> 109200
A25: Gross Revenue (VAT-inclusive) | B25: =Calcs!B41 -> 1706.8296 | C25: =Calcs!B41*Inputs!B7 -> 11947.807 | D25: =Calcs!B41*Calcs!B45 -> 51734.006 | E25: =Calcs!B41*Calcs!B46 -> 621285.99
A26: less: VAT (20%) | B26: =-Calcs!B42 -> -284.47161 | C26: =-Calcs!B42*Inputs!B7 -> -1991.3012 | D26: =-Calcs!B42*Calcs!B45 -> -8622.3344 | E26: =-Calcs!B42*Calcs!B46 -> -103547.66
A27: less: Card Fees | B27: =-Calcs!B43 -> -42.670741 | C27: =-Calcs!B43*Inputs!B7 -> -298.69519 | D27: =-Calcs!B43*Calcs!B45 -> -1293.3502 | E27: =-Calcs!B43*Calcs!B46 -> -15532.15
A28: Net Revenue | B28: =Calcs!B44 -> 1379.6873 | C28: =Calcs!B44*Inputs!B7 -> 9657.811 | D28: =Calcs!B44*Calcs!B45 -> 41818.322 | E28: =Calcs!B44*Calcs!B46 -> 502206.17
A30: Costs (£) — Daily Detail
A31: Staff Wages | B31: =Calcs!B47 -> 132 | C31: =Calcs!B47*Inputs!B7 -> 924 | D31: =Calcs!B47*Calcs!B45 -> 4000.92 | E31: =Calcs!B47*Calcs!B46 -> 48048
A32: Employer NI | B32: =Calcs!B48 -> 18.216 | C32: =Calcs!B48*Inputs!B7 -> 127.512 | D32: =Calcs!B48*Calcs!B45 -> 552.12696 | E32: =Calcs!B48*Calcs!B46 -> 6630.624
A33: Employer Pension | B33: =Calcs!B49 -> 3.96 | C33: =Calcs!B49*Inputs!B7 -> 27.72 | D33: =Calcs!B49*Calcs!B45 -> 120.0276 | E33: =Calcs!B49*Calcs!B46 -> 1441.44
A34: ANPR System | B34: =Calcs!B53 -> 0 | C34: =Calcs!B53*Inputs!B7 -> 0 | D34: =Calcs!B53*Calcs!B45 -> 0 | E34: =Calcs!B53*Calcs!B46 -> 0
A35: Rent | B35: =Calcs!B54 -> 0 | C35: =Calcs!B54*Inputs!B7 -> 0 | D35: =Calcs!B54*Calcs!B45 -> 0 | E35: =Calcs!B54*Calcs!B46 -> 0
A36: Insurance | B36: =Calcs!B55 -> 9.8977235 | C36: =Calcs!B55*Inputs!B7 -> 69.284065 | D36: =Calcs!B55*Calcs!B45 -> 300 | E36: =Calcs!B55*Calcs!B46 -> 3602.7714
A37: Utilities | B37: =Calcs!B56 -> 4.9488618 | C37: =Calcs!B56*Inputs!B7 -> 34.642032 | D37: =Calcs!B56*Calcs!B45 -> 150 | E37: =Calcs!B56*Calcs!B46 -> 1801.3857
A38: Maintenance | B38: =Calcs!B57 -> 6.5984823 | C38: =Calcs!B57*Inputs!B7 -> 46.189376 | D38: =Calcs!B57*Calcs!B45 -> 200 | E38: =Calcs!B57*Calcs!B46 -> 2401.8476
A39: Business Rates | B39: =Calcs!B58 -> 26.393929 | C39: =Calcs!B58*Inputs!B7 -> 184.75751 | D39: =Calcs!B58*Calcs!B45 -> 800 | E39: =Calcs!B58*Calcs!B46 -> 9607.3903
A40: Cleaning | B40: =Calcs!B59 -> 3.2992412 | C40: =Calcs!B59*Inputs!B7 -> 23.094688 | D40: =Calcs!B59*Calcs!B45 -> 100 | E40: =Calcs!B59*Calcs!B46 -> 1200.9238
A41: Other | B41: =Calcs!B60 -> 0 | C41: =Calcs!B60*Inputs!B7 -> 0 | D41: =Calcs!B60*Calcs!B45 -> 0 | E41: =Calcs!B60*Calcs!B46 -> 0
A42: Mortgage | B42: =Calcs!B66 -> 437.21907 | C42: =Calcs!B66*Inputs!B7 -> 3060.5335 | D42: =Calcs!B66*Calcs!B45 -> 13252.11 | E42: =Calcs!B66*Calcs!B46 -> 159147.74
A43: Total Costs | B43: =Calcs!B69 -> 642.53331 | C43: =Calcs!B69*Inputs!B7 -> 4497.7331 | D43: =Calcs!B69*Calcs!B45 -> 19475.185 | E43: =Calcs!B69*Calcs!B46 -> 233882.12
...

Sheet Calcs
A1: Intermediate Calculations
A2: Overnight Cars (capped) | B2: =MIN(Inputs!B28,Inputs!B5) -> 5
A3: Long-Term Spaces (capped) | B3: =MIN(Inputs!B30,Inputs!B5-Calcs!B2) -> 20
A4: Short-Stay Spaces | B4: =MAX(0,Inputs!B5-Calcs!B2-Calcs!B3) -> 55
A5: Indoor Spaces (capped) | B5: =MIN(Inputs!B34,Calcs!B4) -> 20
A6: Outdoor Spaces | B6: =Calcs!B4-Calcs!B5 -> 35
A7: Outdoor Fraction | B7: =IF(Calcs!B4>0,Calcs!B6/Calcs!B4,1) -> 0.63636364
A8: Indoor Fraction | B8: =IF(Calcs!B4>0,Calcs!B5/Calcs!B4,0) -> 0.36363636
A9: Commuter Spaces | B9: =Calcs!B4*Inputs!B11 -> 19.25
A10: Short-Stay Spaces (non-commuter) | B10: =Calcs!B4*(1-Inputs!B11) -> 35.75
A11: Commuter Occupied Spaces | B11: =Calcs!B9*Inputs!B8 -> 9.625
A12: Mix Total | B12: =Inputs!B14+Inputs!B15+Inputs!B16+Inputs!B17 -> 1
A13: Norm Mix Small | B13: =IF(Calcs!B12>0,Inputs!B14/Calcs!B12,1) -> 0.85
A14: Norm Mix Large | B14: =IF(Calcs!B12>0,Inputs!B15/Calcs!B12,0) -> 0.05
A15: Norm Mix SMVan | B15: =IF(Calcs!B12>0,Inputs!B16/Calcs!B12,0) -> 0.05
A16: Norm Mix LVan | B16: =IF(Calcs!B12>0,Inputs!B17/Calcs!B12,0) -> 0.05
A17: Commuter Cost Small (outdoor) | B17: =IF(Inputs!B6>=Inputs!E22,Inputs!D22,MAX(4,CEILING(Inputs!B6,1)*Inputs!C22)) -> 25
A18: Commuter Cost Large (outdoor) | B18: =IF(Inputs!B6>=Inputs!E23,Inputs!D23,MAX(4,CEILING(Inputs!B6,1)*Inputs!C23)) -> 30
A19: Commuter Cost SMVan (outdoor) | B19: =IF(Inputs!B6>=Inputs!E24,Inputs!D24,MAX(4,CEILING(Inputs!B6,1)*Inputs!C24)) -> 30
A20: Commuter Cost LVan (outdoor) | B20: =IF(Inputs!B6>=Inputs!E25,Inputs!D25,MAX(4,CEILING(Inputs!B6,1)*Inputs!C25)) -> 50
A21: Commuter Cost Indoor | B21: =IF(Inputs!B6>=5,Inputs!B36,MAX(4,CEILING(Inputs!B6,1)*Inputs!B35)) -> 30
A22: Commuter Revenue Outdoor | B22: =Calcs!B11*Calcs!B7*(Calcs!B13*Calcs!B17+Calcs!B14*Calcs!B18+Calcs!B15*Calcs!B19+Calcs!B16*Calcs!B20) -> 163.84375
A23: Commuter Revenue Indoor | B23: =Calcs!B11*Calcs!B8*Calcs!B21 -> 105
A24: Commuter Revenue Total | B24: =Calcs!B22+Calcs!B23 -> 268.84375
A25: Dead Time (hours) | B25: =Inputs!B10/60 -> 0.16666667
A26: Effective Stay (hrs) | B26: =Inputs!B9+Calcs!B25 -> 2.0666667
A27: Short-Stay Turnover Rate | B27: =IF(Calcs!B26>0,Inputs!B6/Calcs!B26,0) -> 5.3225806
A28: Short-Stay Occupied Spaces | B28: =Calcs!B10*Inputs!B8 -> 17.875
A29: Short-Stay Vehicles/Day | B29: =Calcs!B28*Calcs!B27 -> 95.141129
A30: SS Cost Small (outdoor) | B30: =IF(Inputs!B9>=Inputs!E22,Inputs!D22,MAX(4,CEILING(Inputs!B9,1)*Inputs!C22)) -> 10
A31: SS Cost Large (outdoor) | B31: =IF(Inputs!B9>=Inputs!E23,Inputs!D23,MAX(4,CEILING(Inputs!B9,1)*Inputs!C23)) -> 12
A32: SS Cost SMVan (outdoor) | B32: =IF(Inputs!B9>=Inputs!E24,Inputs!D24,MAX(4,CEILING(Inputs!B9,1)*Inputs!C24)) -> 12
A33: SS Cost LVan (outdoor) | B33: =IF(Inputs!B9>=Inputs!E25,Inputs!D25,MAX(4,CEILING(Inputs!B9,1)*Inputs!C25)) -> 20
A34: SS Cost Indoor | B34: =IF(Inputs!B9>=5,Inputs!B36,MAX(4,CEILING(Inputs!B9,1)*Inputs!B35)) -> 12
A35: SS Revenue Outdoor | B35: =Calcs!B29*Calcs!B7*(Calcs!B13*Calcs!B30+Calcs!B14*Calcs!B31+Calcs!B15*Calcs!B32+Calcs!B16*Calcs!B33) -> 647.8246
A36: SS Revenue Indoor | B36: =Calcs!B29*Calcs!B8*Calcs!B34 -> 415.16129
A37: SS Revenue Total | B37: =Calcs!B35+Calcs!B36 -> 1062.9859
A38: Daily Parking Revenue (Gross) | B38: =Calcs!B24+Calcs!B37 -> 1331.8296
A39: Daily Overnight Revenue (Gross) | B39: =Calcs!B2*Inputs!B29 -> 75
A40: Daily Long-Term Revenue (Gross) | B40: =Calcs!B3*Inputs!B31/7 -> 300
...
